{"level":"ERROR","location":"[On_message:1442] data_ws","message":"'ltp'","timestamp":"2025-03-07 01:07:43,886+0530","service":"FyersDataSocket","exception":"Traceback (most recent call last):\n  File \"C:\\Python 3.7\\Lib\\site-packages\\fyers_apiv3\\FyersWebsocket\\data_ws.py\", line 1433, in On_message\n    self.OnMessage(message)\n  File \"C:\\Users\\Uranium Oxide\\AppData\\Local\\Temp\\ipykernel_8460\\3371927324.py\", line 4, in onmessage\n    print(\"Response:\", message['ltp'])\n                       ~~~~~~~^^^^^^^\nKeyError: 'ltp'","exception_name":"KeyError"}
{"level":"ERROR","location":"[On_message:1443] data_ws","message":"KeyError: The key 'ltp' is missing in the response.","timestamp":"2025-03-07 01:07:43,922+0530","service":"FyersDataSocket"}
{"level":"ERROR","location":"[On_message:1442] data_ws","message":"'ltp'","timestamp":"2025-03-07 01:07:44,076+0530","service":"FyersDataSocket","exception":"Traceback (most recent call last):\n  File \"C:\\Python 3.7\\Lib\\site-packages\\fyers_apiv3\\FyersWebsocket\\data_ws.py\", line 1433, in On_message\n    self.OnMessage(message)\n  File \"C:\\Users\\Uranium Oxide\\AppData\\Local\\Temp\\ipykernel_8460\\3371927324.py\", line 4, in onmessage\n    print(\"Response:\", message['ltp'])\n                       ~~~~~~~^^^^^^^\nKeyError: 'ltp'","exception_name":"KeyError"}
{"level":"ERROR","location":"[On_message:1443] data_ws","message":"KeyError: The key 'ltp' is missing in the response.","timestamp":"2025-03-07 01:07:44,078+0530","service":"FyersDataSocket"}
{"level":"ERROR","location":"[__symbol_conversion:1352] data_ws","message":{"code":-300,"message":"Please provide a valid symbol","s":"error","type":"sub","invalid_symbols":["MCX:CRUDEOIL24AUGFUT"]},"timestamp":"2025-03-07 01:07:46,109+0530","service":"FyersDataSocket","taskName":"Task-3"}
{"level":"ERROR","location":"[On_message:1442] data_ws","message":"'ltp'","timestamp":"2025-03-07 01:09:49,484+0530","service":"FyersDataSocket","exception":"Traceback (most recent call last):\n  File \"C:\\Python 3.7\\Lib\\site-packages\\fyers_apiv3\\FyersWebsocket\\data_ws.py\", line 1433, in On_message\n    self.OnMessage(message)\n  File \"C:\\Users\\Uranium Oxide\\AppData\\Local\\Temp\\ipykernel_8460\\1791561985.py\", line 5, in onmessage\n    print(\"Response:\", message['ltp'])\n                       ~~~~~~~^^^^^^^\nKeyError: 'ltp'","exception_name":"KeyError"}
{"level":"ERROR","location":"[On_message:1443] data_ws","message":"KeyError: The key 'ltp' is missing in the response.","timestamp":"2025-03-07 01:09:49,489+0530","service":"FyersDataSocket"}
{"level":"ERROR","location":"[On_message:1442] data_ws","message":"'ltp'","timestamp":"2025-03-07 01:09:49,629+0530","service":"FyersDataSocket","exception":"Traceback (most recent call last):\n  File \"C:\\Python 3.7\\Lib\\site-packages\\fyers_apiv3\\FyersWebsocket\\data_ws.py\", line 1433, in On_message\n    self.OnMessage(message)\n  File \"C:\\Users\\Uranium Oxide\\AppData\\Local\\Temp\\ipykernel_8460\\1791561985.py\", line 5, in onmessage\n    print(\"Response:\", message['ltp'])\n                       ~~~~~~~^^^^^^^\nKeyError: 'ltp'","exception_name":"KeyError"}
{"level":"ERROR","location":"[On_message:1443] data_ws","message":"KeyError: The key 'ltp' is missing in the response.","timestamp":"2025-03-07 01:09:49,630+0530","service":"FyersDataSocket"}
{"level":"ERROR","location":"[On_message:1442] data_ws","message":"'ltp'","timestamp":"2025-03-07 01:09:52,234+0530","service":"FyersDataSocket","exception":"Traceback (most recent call last):\n  File \"C:\\Python 3.7\\Lib\\site-packages\\fyers_apiv3\\FyersWebsocket\\data_ws.py\", line 1433, in On_message\n    self.OnMessage(message)\n  File \"C:\\Users\\Uranium Oxide\\AppData\\Local\\Temp\\ipykernel_8460\\1791561985.py\", line 5, in onmessage\n    print(\"Response:\", message['ltp'])\n                       ~~~~~~~^^^^^^^\nKeyError: 'ltp'","exception_name":"KeyError"}
{"level":"ERROR","location":"[On_message:1443] data_ws","message":"KeyError: The key 'ltp' is missing in the response.","timestamp":"2025-03-07 01:09:52,235+0530","service":"FyersDataSocket"}
{"level":"ERROR","location":"[<lambda>:1663] data_ws","message":"Connection to remote host was lost.","timestamp":"2025-03-07 03:02:16,493+0530","service":"FyersDataSocket"}
{"level":"ERROR","location":"[<lambda>:1663] data_ws","message":"Connection to remote host was lost.","timestamp":"2025-03-07 03:02:16,493+0530","service":"FyersDataSocket"}
{"level":"ERROR","location":"[<lambda>:1663] data_ws","message":"Connection to remote host was lost.","timestamp":"2025-03-07 03:02:16,494+0530","service":"FyersDataSocket"}
{"level":"ERROR","location":"[<lambda>:1663] data_ws","message":"Connection to remote host was lost.","timestamp":"2025-03-07 03:02:16,499+0530","service":"FyersDataSocket"}
{"level":"ERROR","location":"[<lambda>:1663] data_ws","message":"Connection to remote host was lost.","timestamp":"2025-03-07 03:02:16,500+0530","service":"FyersDataSocket"}
{"level":"ERROR","location":"[<lambda>:1663] data_ws","message":"Connection to remote host was lost.","timestamp":"2025-03-07 03:02:16,501+0530","service":"FyersDataSocket"}
{"level":"ERROR","location":"[<lambda>:1663] data_ws","message":"Connection to remote host was lost.","timestamp":"2025-03-07 03:02:16,501+0530","service":"FyersDataSocket"}
{"level":"ERROR","location":"[access_token_to_hsmtoken:272] data_ws","message":{"type":"cn","code":-99,"message":"Token is expired","s":"error"},"timestamp":"2025-03-07 06:51:37,481+0530","service":"FyersDataSocket"}
{"level":"ERROR","location":"[access_token_to_hsmtoken:272] data_ws","message":{"type":"cn","code":-99,"message":"Token is expired","s":"error"},"timestamp":"2025-03-07 06:51:37,482+0530","service":"FyersDataSocket"}
{"level":"ERROR","location":"[access_token_to_hsmtoken:272] data_ws","message":{"type":"cn","code":-99,"message":"Token is expired","s":"error"},"timestamp":"2025-03-07 06:51:37,483+0530","service":"FyersDataSocket"}
{"level":"ERROR","location":"[access_token_to_hsmtoken:272] data_ws","message":{"type":"cn","code":-99,"message":"Token is expired","s":"error"},"timestamp":"2025-03-07 06:51:37,509+0530","service":"FyersDataSocket"}
{"level":"ERROR","location":"[access_token_to_hsmtoken:272] data_ws","message":{"type":"cn","code":-99,"message":"Token is expired","s":"error"},"timestamp":"2025-03-07 06:51:37,509+0530","service":"FyersDataSocket"}
{"level":"ERROR","location":"[access_token_to_hsmtoken:272] data_ws","message":{"type":"cn","code":-99,"message":"Token is expired","s":"error"},"timestamp":"2025-03-07 06:51:37,509+0530","service":"FyersDataSocket"}
{"level":"ERROR","location":"[access_token_to_hsmtoken:272] data_ws","message":{"type":"cn","code":-99,"message":"Token is expired","s":"error"},"timestamp":"2025-03-07 06:51:37,510+0530","service":"FyersDataSocket"}
{"level":"ERROR","location":"[on_open:1519] data_ws","message":"'FyersModel' object has no attribute 'subscribe'","timestamp":"2025-03-07 06:51:39,483+0530","service":"FyersDataSocket","exception":"Traceback (most recent call last):\n  File \"C:\\Python 3.7\\Lib\\site-packages\\websocket\\_app.py\", line 428, in setSock\n    dispatcher.read(self.sock.sock, read, check)\n  File \"C:\\Python 3.7\\Lib\\site-packages\\websocket\\_app.py\", line 99, in read\n    if not read_callback():\n           ^^^^^^^^^^^^^^^\n  File \"C:\\Python 3.7\\Lib\\site-packages\\websocket\\_app.py\", line 442, in read\n    raise e\n  File \"C:\\Python 3.7\\Lib\\site-packages\\websocket\\_app.py\", line 437, in read\n    op_code, frame = self.sock.recv_data_frame(True)\n                     ^^^^^^^^^^^^^^^^^^^^^^^^^^^^^^^\n  File \"C:\\Python 3.7\\Lib\\site-packages\\websocket\\_core.py\", line 406, in recv_data_frame\n    frame = self.recv_frame()\n            ^^^^^^^^^^^^^^^^^\n  File \"C:\\Python 3.7\\Lib\\site-packages\\websocket\\_core.py\", line 445, in recv_frame\n    return self.frame_buffer.recv_frame()\n           ^^^^^^^^^^^^^^^^^^^^^^^^^^^^^^\n  File \"C:\\Python 3.7\\Lib\\site-packages\\websocket\\_abnf.py\", line 338, in recv_frame\n    self.recv_header()\n  File \"C:\\Python 3.7\\Lib\\site-packages\\websocket\\_abnf.py\", line 294, in recv_header\n    header = self.recv_strict(2)\n             ^^^^^^^^^^^^^^^^^^^\n  File \"C:\\Python 3.7\\Lib\\site-packages\\websocket\\_abnf.py\", line 373, in recv_strict\n    bytes_ = self.recv(min(16384, shortage))\n             ^^^^^^^^^^^^^^^^^^^^^^^^^^^^^^^\n  File \"C:\\Python 3.7\\Lib\\site-packages\\websocket\\_core.py\", line 529, in _recv\n    return recv(self.sock, bufsize)\n           ^^^^^^^^^^^^^^^^^^^^^^^^\n  File \"C:\\Python 3.7\\Lib\\site-packages\\websocket\\_socket.py\", line 122, in recv\n    raise WebSocketConnectionClosedException(\nwebsocket._exceptions.WebSocketConnectionClosedException: Connection to remote host was lost.\n\nDuring handling of the above exception, another exception occurred:\n\nTraceback (most recent call last):\n  File \"C:\\Python 3.7\\Lib\\site-packages\\fyers_apiv3\\FyersWebsocket\\data_ws.py\", line 1517, in on_open\n    self.OnOpen()\n  File \"C:\\Users\\Uranium Oxide\\AppData\\Local\\Temp\\ipykernel_8460\\3090056784.py\", line 20, in onopen\n    fyers.subscribe(symbols=symbols, data_type=data_type)\n    ^^^^^^^^^^^^^^^\nAttributeError: 'FyersModel' object has no attribute 'subscribe'","exception_name":"AttributeError"}
{"level":"ERROR","location":"[on_open:1519] data_ws","message":"'FyersModel' object has no attribute 'subscribe'","timestamp":"2025-03-07 06:51:39,485+0530","service":"FyersDataSocket","exception":"Traceback (most recent call last):\n  File \"C:\\Python 3.7\\Lib\\site-packages\\websocket\\_app.py\", line 428, in setSock\n    dispatcher.read(self.sock.sock, read, check)\n  File \"C:\\Python 3.7\\Lib\\site-packages\\websocket\\_app.py\", line 99, in read\n    if not read_callback():\n           ^^^^^^^^^^^^^^^\n  File \"C:\\Python 3.7\\Lib\\site-packages\\websocket\\_app.py\", line 442, in read\n    raise e\n  File \"C:\\Python 3.7\\Lib\\site-packages\\websocket\\_app.py\", line 437, in read\n    op_code, frame = self.sock.recv_data_frame(True)\n                     ^^^^^^^^^^^^^^^^^^^^^^^^^^^^^^^\n  File \"C:\\Python 3.7\\Lib\\site-packages\\websocket\\_core.py\", line 406, in recv_data_frame\n    frame = self.recv_frame()\n            ^^^^^^^^^^^^^^^^^\n  File \"C:\\Python 3.7\\Lib\\site-packages\\websocket\\_core.py\", line 445, in recv_frame\n    return self.frame_buffer.recv_frame()\n           ^^^^^^^^^^^^^^^^^^^^^^^^^^^^^^\n  File \"C:\\Python 3.7\\Lib\\site-packages\\websocket\\_abnf.py\", line 338, in recv_frame\n    self.recv_header()\n  File \"C:\\Python 3.7\\Lib\\site-packages\\websocket\\_abnf.py\", line 294, in recv_header\n    header = self.recv_strict(2)\n             ^^^^^^^^^^^^^^^^^^^\n  File \"C:\\Python 3.7\\Lib\\site-packages\\websocket\\_abnf.py\", line 373, in recv_strict\n    bytes_ = self.recv(min(16384, shortage))\n             ^^^^^^^^^^^^^^^^^^^^^^^^^^^^^^^\n  File \"C:\\Python 3.7\\Lib\\site-packages\\websocket\\_core.py\", line 529, in _recv\n    return recv(self.sock, bufsize)\n           ^^^^^^^^^^^^^^^^^^^^^^^^\n  File \"C:\\Python 3.7\\Lib\\site-packages\\websocket\\_socket.py\", line 122, in recv\n    raise WebSocketConnectionClosedException(\nwebsocket._exceptions.WebSocketConnectionClosedException: Connection to remote host was lost.\n\nDuring handling of the above exception, another exception occurred:\n\nTraceback (most recent call last):\n  File \"C:\\Python 3.7\\Lib\\site-packages\\fyers_apiv3\\FyersWebsocket\\data_ws.py\", line 1517, in on_open\n    self.OnOpen()\n  File \"C:\\Users\\Uranium Oxide\\AppData\\Local\\Temp\\ipykernel_8460\\3090056784.py\", line 20, in onopen\n    fyers.subscribe(symbols=symbols, data_type=data_type)\n    ^^^^^^^^^^^^^^^\nAttributeError: 'FyersModel' object has no attribute 'subscribe'","exception_name":"AttributeError"}
{"level":"ERROR","location":"[on_open:1519] data_ws","message":"'FyersModel' object has no attribute 'subscribe'","timestamp":"2025-03-07 06:51:39,485+0530","service":"FyersDataSocket","exception":"Traceback (most recent call last):\n  File \"C:\\Python 3.7\\Lib\\site-packages\\websocket\\_app.py\", line 428, in setSock\n    dispatcher.read(self.sock.sock, read, check)\n  File \"C:\\Python 3.7\\Lib\\site-packages\\websocket\\_app.py\", line 99, in read\n    if not read_callback():\n           ^^^^^^^^^^^^^^^\n  File \"C:\\Python 3.7\\Lib\\site-packages\\websocket\\_app.py\", line 442, in read\n    raise e\n  File \"C:\\Python 3.7\\Lib\\site-packages\\websocket\\_app.py\", line 437, in read\n    op_code, frame = self.sock.recv_data_frame(True)\n                     ^^^^^^^^^^^^^^^^^^^^^^^^^^^^^^^\n  File \"C:\\Python 3.7\\Lib\\site-packages\\websocket\\_core.py\", line 406, in recv_data_frame\n    frame = self.recv_frame()\n            ^^^^^^^^^^^^^^^^^\n  File \"C:\\Python 3.7\\Lib\\site-packages\\websocket\\_core.py\", line 445, in recv_frame\n    return self.frame_buffer.recv_frame()\n           ^^^^^^^^^^^^^^^^^^^^^^^^^^^^^^\n  File \"C:\\Python 3.7\\Lib\\site-packages\\websocket\\_abnf.py\", line 338, in recv_frame\n    self.recv_header()\n  File \"C:\\Python 3.7\\Lib\\site-packages\\websocket\\_abnf.py\", line 294, in recv_header\n    header = self.recv_strict(2)\n             ^^^^^^^^^^^^^^^^^^^\n  File \"C:\\Python 3.7\\Lib\\site-packages\\websocket\\_abnf.py\", line 373, in recv_strict\n    bytes_ = self.recv(min(16384, shortage))\n             ^^^^^^^^^^^^^^^^^^^^^^^^^^^^^^^\n  File \"C:\\Python 3.7\\Lib\\site-packages\\websocket\\_core.py\", line 529, in _recv\n    return recv(self.sock, bufsize)\n           ^^^^^^^^^^^^^^^^^^^^^^^^\n  File \"C:\\Python 3.7\\Lib\\site-packages\\websocket\\_socket.py\", line 122, in recv\n    raise WebSocketConnectionClosedException(\nwebsocket._exceptions.WebSocketConnectionClosedException: Connection to remote host was lost.\n\nDuring handling of the above exception, another exception occurred:\n\nTraceback (most recent call last):\n  File \"C:\\Python 3.7\\Lib\\site-packages\\fyers_apiv3\\FyersWebsocket\\data_ws.py\", line 1517, in on_open\n    self.OnOpen()\n  File \"C:\\Users\\Uranium Oxide\\AppData\\Local\\Temp\\ipykernel_8460\\3090056784.py\", line 20, in onopen\n    fyers.subscribe(symbols=symbols, data_type=data_type)\n    ^^^^^^^^^^^^^^^\nAttributeError: 'FyersModel' object has no attribute 'subscribe'","exception_name":"AttributeError"}
{"level":"ERROR","location":"[on_open:1519] data_ws","message":"'FyersModel' object has no attribute 'subscribe'","timestamp":"2025-03-07 06:51:39,509+0530","service":"FyersDataSocket","exception":"Traceback (most recent call last):\n  File \"C:\\Python 3.7\\Lib\\site-packages\\websocket\\_app.py\", line 428, in setSock\n    dispatcher.read(self.sock.sock, read, check)\n  File \"C:\\Python 3.7\\Lib\\site-packages\\websocket\\_app.py\", line 99, in read\n    if not read_callback():\n           ^^^^^^^^^^^^^^^\n  File \"C:\\Python 3.7\\Lib\\site-packages\\websocket\\_app.py\", line 442, in read\n    raise e\n  File \"C:\\Python 3.7\\Lib\\site-packages\\websocket\\_app.py\", line 437, in read\n    op_code, frame = self.sock.recv_data_frame(True)\n                     ^^^^^^^^^^^^^^^^^^^^^^^^^^^^^^^\n  File \"C:\\Python 3.7\\Lib\\site-packages\\websocket\\_core.py\", line 406, in recv_data_frame\n    frame = self.recv_frame()\n            ^^^^^^^^^^^^^^^^^\n  File \"C:\\Python 3.7\\Lib\\site-packages\\websocket\\_core.py\", line 445, in recv_frame\n    return self.frame_buffer.recv_frame()\n           ^^^^^^^^^^^^^^^^^^^^^^^^^^^^^^\n  File \"C:\\Python 3.7\\Lib\\site-packages\\websocket\\_abnf.py\", line 338, in recv_frame\n    self.recv_header()\n  File \"C:\\Python 3.7\\Lib\\site-packages\\websocket\\_abnf.py\", line 294, in recv_header\n    header = self.recv_strict(2)\n             ^^^^^^^^^^^^^^^^^^^\n  File \"C:\\Python 3.7\\Lib\\site-packages\\websocket\\_abnf.py\", line 373, in recv_strict\n    bytes_ = self.recv(min(16384, shortage))\n             ^^^^^^^^^^^^^^^^^^^^^^^^^^^^^^^\n  File \"C:\\Python 3.7\\Lib\\site-packages\\websocket\\_core.py\", line 529, in _recv\n    return recv(self.sock, bufsize)\n           ^^^^^^^^^^^^^^^^^^^^^^^^\n  File \"C:\\Python 3.7\\Lib\\site-packages\\websocket\\_socket.py\", line 122, in recv\n    raise WebSocketConnectionClosedException(\nwebsocket._exceptions.WebSocketConnectionClosedException: Connection to remote host was lost.\n\nDuring handling of the above exception, another exception occurred:\n\nTraceback (most recent call last):\n  File \"C:\\Python 3.7\\Lib\\site-packages\\fyers_apiv3\\FyersWebsocket\\data_ws.py\", line 1517, in on_open\n    self.OnOpen()\n  File \"C:\\Users\\Uranium Oxide\\AppData\\Local\\Temp\\ipykernel_8460\\3090056784.py\", line 20, in onopen\n    fyers.subscribe(symbols=symbols, data_type=data_type)\n    ^^^^^^^^^^^^^^^\nAttributeError: 'FyersModel' object has no attribute 'subscribe'","exception_name":"AttributeError"}
{"level":"ERROR","location":"[on_open:1520] data_ws","message":"'FyersModel' object has no attribute 'subscribe'","timestamp":"2025-03-07 06:51:39,536+0530","service":"FyersDataSocket"}
{"level":"ERROR","location":"[on_open:1519] data_ws","message":"'FyersModel' object has no attribute 'subscribe'","timestamp":"2025-03-07 06:51:39,510+0530","service":"FyersDataSocket","exception":"Traceback (most recent call last):\n  File \"C:\\Python 3.7\\Lib\\site-packages\\websocket\\_app.py\", line 428, in setSock\n    dispatcher.read(self.sock.sock, read, check)\n  File \"C:\\Python 3.7\\Lib\\site-packages\\websocket\\_app.py\", line 99, in read\n    if not read_callback():\n           ^^^^^^^^^^^^^^^\n  File \"C:\\Python 3.7\\Lib\\site-packages\\websocket\\_app.py\", line 442, in read\n    raise e\n  File \"C:\\Python 3.7\\Lib\\site-packages\\websocket\\_app.py\", line 437, in read\n    op_code, frame = self.sock.recv_data_frame(True)\n                     ^^^^^^^^^^^^^^^^^^^^^^^^^^^^^^^\n  File \"C:\\Python 3.7\\Lib\\site-packages\\websocket\\_core.py\", line 406, in recv_data_frame\n    frame = self.recv_frame()\n            ^^^^^^^^^^^^^^^^^\n  File \"C:\\Python 3.7\\Lib\\site-packages\\websocket\\_core.py\", line 445, in recv_frame\n    return self.frame_buffer.recv_frame()\n           ^^^^^^^^^^^^^^^^^^^^^^^^^^^^^^\n  File \"C:\\Python 3.7\\Lib\\site-packages\\websocket\\_abnf.py\", line 338, in recv_frame\n    self.recv_header()\n  File \"C:\\Python 3.7\\Lib\\site-packages\\websocket\\_abnf.py\", line 294, in recv_header\n    header = self.recv_strict(2)\n             ^^^^^^^^^^^^^^^^^^^\n  File \"C:\\Python 3.7\\Lib\\site-packages\\websocket\\_abnf.py\", line 373, in recv_strict\n    bytes_ = self.recv(min(16384, shortage))\n             ^^^^^^^^^^^^^^^^^^^^^^^^^^^^^^^\n  File \"C:\\Python 3.7\\Lib\\site-packages\\websocket\\_core.py\", line 529, in _recv\n    return recv(self.sock, bufsize)\n           ^^^^^^^^^^^^^^^^^^^^^^^^\n  File \"C:\\Python 3.7\\Lib\\site-packages\\websocket\\_socket.py\", line 122, in recv\n    raise WebSocketConnectionClosedException(\nwebsocket._exceptions.WebSocketConnectionClosedException: Connection to remote host was lost.\n\nDuring handling of the above exception, another exception occurred:\n\nTraceback (most recent call last):\n  File \"C:\\Python 3.7\\Lib\\site-packages\\fyers_apiv3\\FyersWebsocket\\data_ws.py\", line 1517, in on_open\n    self.OnOpen()\n  File \"C:\\Users\\Uranium Oxide\\AppData\\Local\\Temp\\ipykernel_8460\\3090056784.py\", line 20, in onopen\n    fyers.subscribe(symbols=symbols, data_type=data_type)\n    ^^^^^^^^^^^^^^^\nAttributeError: 'FyersModel' object has no attribute 'subscribe'","exception_name":"AttributeError"}
{"level":"ERROR","location":"[on_open:1519] data_ws","message":"'FyersModel' object has no attribute 'subscribe'","timestamp":"2025-03-07 06:51:39,510+0530","service":"FyersDataSocket","exception":"Traceback (most recent call last):\n  File \"C:\\Python 3.7\\Lib\\site-packages\\websocket\\_app.py\", line 428, in setSock\n    dispatcher.read(self.sock.sock, read, check)\n  File \"C:\\Python 3.7\\Lib\\site-packages\\websocket\\_app.py\", line 99, in read\n    if not read_callback():\n           ^^^^^^^^^^^^^^^\n  File \"C:\\Python 3.7\\Lib\\site-packages\\websocket\\_app.py\", line 442, in read\n    raise e\n  File \"C:\\Python 3.7\\Lib\\site-packages\\websocket\\_app.py\", line 437, in read\n    op_code, frame = self.sock.recv_data_frame(True)\n                     ^^^^^^^^^^^^^^^^^^^^^^^^^^^^^^^\n  File \"C:\\Python 3.7\\Lib\\site-packages\\websocket\\_core.py\", line 406, in recv_data_frame\n    frame = self.recv_frame()\n            ^^^^^^^^^^^^^^^^^\n  File \"C:\\Python 3.7\\Lib\\site-packages\\websocket\\_core.py\", line 445, in recv_frame\n    return self.frame_buffer.recv_frame()\n           ^^^^^^^^^^^^^^^^^^^^^^^^^^^^^^\n  File \"C:\\Python 3.7\\Lib\\site-packages\\websocket\\_abnf.py\", line 338, in recv_frame\n    self.recv_header()\n  File \"C:\\Python 3.7\\Lib\\site-packages\\websocket\\_abnf.py\", line 294, in recv_header\n    header = self.recv_strict(2)\n             ^^^^^^^^^^^^^^^^^^^\n  File \"C:\\Python 3.7\\Lib\\site-packages\\websocket\\_abnf.py\", line 373, in recv_strict\n    bytes_ = self.recv(min(16384, shortage))\n             ^^^^^^^^^^^^^^^^^^^^^^^^^^^^^^^\n  File \"C:\\Python 3.7\\Lib\\site-packages\\websocket\\_core.py\", line 529, in _recv\n    return recv(self.sock, bufsize)\n           ^^^^^^^^^^^^^^^^^^^^^^^^\n  File \"C:\\Python 3.7\\Lib\\site-packages\\websocket\\_socket.py\", line 122, in recv\n    raise WebSocketConnectionClosedException(\nwebsocket._exceptions.WebSocketConnectionClosedException: Connection to remote host was lost.\n\nDuring handling of the above exception, another exception occurred:\n\nTraceback (most recent call last):\n  File \"C:\\Python 3.7\\Lib\\site-packages\\fyers_apiv3\\FyersWebsocket\\data_ws.py\", line 1517, in on_open\n    self.OnOpen()\n  File \"C:\\Users\\Uranium Oxide\\AppData\\Local\\Temp\\ipykernel_8460\\3090056784.py\", line 20, in onopen\n    fyers.subscribe(symbols=symbols, data_type=data_type)\n    ^^^^^^^^^^^^^^^\nAttributeError: 'FyersModel' object has no attribute 'subscribe'","exception_name":"AttributeError"}
{"level":"ERROR","location":"[on_open:1520] data_ws","message":"'FyersModel' object has no attribute 'subscribe'","timestamp":"2025-03-07 06:51:39,528+0530","service":"FyersDataSocket"}
{"level":"ERROR","location":"[on_open:1520] data_ws","message":"'FyersModel' object has no attribute 'subscribe'","timestamp":"2025-03-07 06:51:39,532+0530","service":"FyersDataSocket"}
{"level":"ERROR","location":"[on_open:1520] data_ws","message":"'FyersModel' object has no attribute 'subscribe'","timestamp":"2025-03-07 06:51:39,534+0530","service":"FyersDataSocket"}
{"level":"ERROR","location":"[on_open:1519] data_ws","message":"'FyersModel' object has no attribute 'subscribe'","timestamp":"2025-03-07 06:51:39,510+0530","service":"FyersDataSocket","exception":"Traceback (most recent call last):\n  File \"C:\\Python 3.7\\Lib\\site-packages\\websocket\\_app.py\", line 428, in setSock\n    dispatcher.read(self.sock.sock, read, check)\n  File \"C:\\Python 3.7\\Lib\\site-packages\\websocket\\_app.py\", line 99, in read\n    if not read_callback():\n           ^^^^^^^^^^^^^^^\n  File \"C:\\Python 3.7\\Lib\\site-packages\\websocket\\_app.py\", line 442, in read\n    raise e\n  File \"C:\\Python 3.7\\Lib\\site-packages\\websocket\\_app.py\", line 437, in read\n    op_code, frame = self.sock.recv_data_frame(True)\n                     ^^^^^^^^^^^^^^^^^^^^^^^^^^^^^^^\n  File \"C:\\Python 3.7\\Lib\\site-packages\\websocket\\_core.py\", line 406, in recv_data_frame\n    frame = self.recv_frame()\n            ^^^^^^^^^^^^^^^^^\n  File \"C:\\Python 3.7\\Lib\\site-packages\\websocket\\_core.py\", line 445, in recv_frame\n    return self.frame_buffer.recv_frame()\n           ^^^^^^^^^^^^^^^^^^^^^^^^^^^^^^\n  File \"C:\\Python 3.7\\Lib\\site-packages\\websocket\\_abnf.py\", line 338, in recv_frame\n    self.recv_header()\n  File \"C:\\Python 3.7\\Lib\\site-packages\\websocket\\_abnf.py\", line 294, in recv_header\n    header = self.recv_strict(2)\n             ^^^^^^^^^^^^^^^^^^^\n  File \"C:\\Python 3.7\\Lib\\site-packages\\websocket\\_abnf.py\", line 373, in recv_strict\n    bytes_ = self.recv(min(16384, shortage))\n             ^^^^^^^^^^^^^^^^^^^^^^^^^^^^^^^\n  File \"C:\\Python 3.7\\Lib\\site-packages\\websocket\\_core.py\", line 529, in _recv\n    return recv(self.sock, bufsize)\n           ^^^^^^^^^^^^^^^^^^^^^^^^\n  File \"C:\\Python 3.7\\Lib\\site-packages\\websocket\\_socket.py\", line 122, in recv\n    raise WebSocketConnectionClosedException(\nwebsocket._exceptions.WebSocketConnectionClosedException: Connection to remote host was lost.\n\nDuring handling of the above exception, another exception occurred:\n\nTraceback (most recent call last):\n  File \"C:\\Python 3.7\\Lib\\site-packages\\fyers_apiv3\\FyersWebsocket\\data_ws.py\", line 1517, in on_open\n    self.OnOpen()\n  File \"C:\\Users\\Uranium Oxide\\AppData\\Local\\Temp\\ipykernel_8460\\3090056784.py\", line 20, in onopen\n    fyers.subscribe(symbols=symbols, data_type=data_type)\n    ^^^^^^^^^^^^^^^\nAttributeError: 'FyersModel' object has no attribute 'subscribe'","exception_name":"AttributeError"}
{"level":"ERROR","location":"[on_open:1520] data_ws","message":"'FyersModel' object has no attribute 'subscribe'","timestamp":"2025-03-07 06:51:39,539+0530","service":"FyersDataSocket"}
{"level":"ERROR","location":"[on_open:1520] data_ws","message":"'FyersModel' object has no attribute 'subscribe'","timestamp":"2025-03-07 06:51:39,541+0530","service":"FyersDataSocket"}
{"level":"ERROR","location":"[on_open:1520] data_ws","message":"'FyersModel' object has no attribute 'subscribe'","timestamp":"2025-03-07 06:51:39,546+0530","service":"FyersDataSocket"}
{"level":"ERROR","location":"[<lambda>:1663] data_ws","message":"Connection to remote host was lost.","timestamp":"2025-03-08 23:31:11,246+0530","service":"FyersDataSocket"}
{"level":"ERROR","location":"[__symbol_conversion:1352] data_ws","message":{"code":-300,"message":"Please provide a valid symbol","s":"error","type":"sub","invalid_symbols":["MCX:CRUDEOILM25MARFU"]},"timestamp":"2025-03-08 23:41:01,904+0530","service":"FyersDataSocket"}
{"level":"ERROR","location":"[<lambda>:1663] data_ws","message":"Connection to remote host was lost.","timestamp":"2025-03-08 23:54:24,228+0530","service":"FyersDataSocket"}
{"level":"ERROR","location":"[<lambda>:1663] data_ws","message":"Connection to remote host was lost.","timestamp":"2025-03-08 23:55:52,870+0530","service":"FyersDataSocket"}
{"level":"ERROR","location":"[<lambda>:1663] data_ws","message":"Connection to remote host was lost.","timestamp":"2025-03-08 23:56:54,251+0530","service":"FyersDataSocket"}
{"level":"ERROR","location":"[<lambda>:1663] data_ws","message":"Connection to remote host was lost.","timestamp":"2025-03-08 23:57:58,172+0530","service":"FyersDataSocket"}
{"level":"ERROR","location":"[On_message:1446] data_ws","message":"livedata.onmessage() takes 1 positional argument but 2 were given","timestamp":"2025-03-09 00:15:33,545+0530","service":"FyersDataSocket","exception":"Traceback (most recent call last):\n  File \"C:\\Python 3.7\\Lib\\site-packages\\fyers_apiv3\\FyersWebsocket\\data_ws.py\", line 1433, in On_message\n    self.OnMessage(message)\nTypeError: livedata.onmessage() takes 1 positional argument but 2 were given","exception_name":"TypeError"}
{"level":"ERROR","location":"[On_message:1447] data_ws","message":"livedata.onmessage() takes 1 positional argument but 2 were given","timestamp":"2025-03-09 00:15:33,551+0530","service":"FyersDataSocket"}
{"level":"ERROR","location":"[On_message:1446] data_ws","message":"livedata.onmessage() takes 1 positional argument but 2 were given","timestamp":"2025-03-09 00:15:33,707+0530","service":"FyersDataSocket","exception":"Traceback (most recent call last):\n  File \"C:\\Python 3.7\\Lib\\site-packages\\fyers_apiv3\\FyersWebsocket\\data_ws.py\", line 1433, in On_message\n    self.OnMessage(message)\nTypeError: livedata.onmessage() takes 1 positional argument but 2 were given","exception_name":"TypeError"}
{"level":"ERROR","location":"[On_message:1447] data_ws","message":"livedata.onmessage() takes 1 positional argument but 2 were given","timestamp":"2025-03-09 00:15:33,709+0530","service":"FyersDataSocket"}
{"level":"ERROR","location":"[On_message:1446] data_ws","message":"livedata.onmessage() takes 1 positional argument but 2 were given","timestamp":"2025-03-09 00:15:36,320+0530","service":"FyersDataSocket","exception":"Traceback (most recent call last):\n  File \"C:\\Python 3.7\\Lib\\site-packages\\fyers_apiv3\\FyersWebsocket\\data_ws.py\", line 1433, in On_message\n    self.OnMessage(message)\nTypeError: livedata.onmessage() takes 1 positional argument but 2 were given","exception_name":"TypeError"}
{"level":"ERROR","location":"[On_message:1447] data_ws","message":"livedata.onmessage() takes 1 positional argument but 2 were given","timestamp":"2025-03-09 00:15:36,323+0530","service":"FyersDataSocket"}
{"level":"ERROR","location":"[On_message:1446] data_ws","message":"livedata.onmessage() takes 1 positional argument but 2 were given","timestamp":"2025-03-09 00:15:36,332+0530","service":"FyersDataSocket","exception":"Traceback (most recent call last):\n  File \"C:\\Python 3.7\\Lib\\site-packages\\fyers_apiv3\\FyersWebsocket\\data_ws.py\", line 1433, in On_message\n    self.OnMessage(message)\nTypeError: livedata.onmessage() takes 1 positional argument but 2 were given","exception_name":"TypeError"}
{"level":"ERROR","location":"[On_message:1447] data_ws","message":"livedata.onmessage() takes 1 positional argument but 2 were given","timestamp":"2025-03-09 00:15:36,333+0530","service":"FyersDataSocket"}
{"level":"ERROR","location":"[<lambda>:1663] data_ws","message":"Connection to remote host was lost.","timestamp":"2025-03-09 00:23:06,686+0530","service":"FyersDataSocket"}
{"level":"ERROR","location":"[<lambda>:1663] data_ws","message":"Connection to remote host was lost.","timestamp":"2025-03-09 00:24:06,689+0530","service":"FyersDataSocket"}
{"level":"ERROR","location":"[<lambda>:1663] data_ws","message":"Connection to remote host was lost.","timestamp":"2025-03-09 00:25:52,775+0530","service":"FyersDataSocket"}
{"level":"ERROR","location":"[<lambda>:1663] data_ws","message":"Connection to remote host was lost.","timestamp":"2025-03-09 00:26:56,713+0530","service":"FyersDataSocket"}
{"level":"ERROR","location":"[<lambda>:1663] data_ws","message":"Connection to remote host was lost.","timestamp":"2025-03-09 00:27:57,992+0530","service":"FyersDataSocket"}
{"level":"ERROR","location":"[<lambda>:1663] data_ws","message":"Connection to remote host was lost.","timestamp":"2025-03-09 00:29:12,782+0530","service":"FyersDataSocket"}
{"level":"ERROR","location":"[<lambda>:1663] data_ws","message":"Connection to remote host was lost.","timestamp":"2025-03-09 00:30:16,735+0530","service":"FyersDataSocket"}
{"level":"ERROR","location":"[<lambda>:1663] data_ws","message":"Connection to remote host was lost.","timestamp":"2025-03-09 00:31:17,978+0530","service":"FyersDataSocket"}
{"level":"ERROR","location":"[<lambda>:1663] data_ws","message":"Connection to remote host was lost.","timestamp":"2025-03-09 00:32:32,774+0530","service":"FyersDataSocket"}
{"level":"ERROR","location":"[<lambda>:1663] data_ws","message":"Connection to remote host was lost.","timestamp":"2025-03-09 18:57:48,735+0530","service":"FyersDataSocket"}
{"level":"ERROR","location":"[<lambda>:1663] data_ws","message":"Connection to remote host was lost.","timestamp":"2025-03-10 13:08:12,869+0530","service":"FyersDataSocket"}
{"level":"ERROR","location":"[<lambda>:1663] data_ws","message":"Connection to remote host was lost.","timestamp":"2025-03-13 01:18:14,877+0530","service":"FyersDataSocket"}
{"level":"ERROR","location":"[<lambda>:1663] data_ws","message":"Connection to remote host was lost.","timestamp":"2025-03-13 01:21:31,624+0530","service":"FyersDataSocket"}
{"level":"ERROR","location":"[<lambda>:1663] data_ws","message":"[WinError 10054] An existing connection was forcibly closed by the remote host","timestamp":"2025-03-13 01:23:18,915+0530","service":"FyersDataSocket"}
{"level":"ERROR","location":"[<lambda>:1663] data_ws","message":"[WinError 10054] An existing connection was forcibly closed by the remote host","timestamp":"2025-03-13 01:23:18,921+0530","service":"FyersDataSocket"}
{"level":"ERROR","location":"[<lambda>:1663] data_ws","message":"[Errno 11001] getaddrinfo failed","timestamp":"2025-03-13 01:23:35,001+0530","service":"FyersDataSocket"}
{"level":"ERROR","location":"[<lambda>:1663] data_ws","message":"[Errno 11001] getaddrinfo failed","timestamp":"2025-03-13 01:23:51,110+0530","service":"FyersDataSocket"}
{"level":"ERROR","location":"[<lambda>:1663] data_ws","message":"[Errno 11001] getaddrinfo failed","timestamp":"2025-03-13 01:23:56,120+0530","service":"FyersDataSocket"}
{"level":"ERROR","location":"[<lambda>:1663] data_ws","message":"[Errno 11001] getaddrinfo failed","timestamp":"2025-03-13 01:24:12,224+0530","service":"FyersDataSocket"}
{"level":"ERROR","location":"[exception:108] fyers_logger","message":"HTTPSConnectionPool(host='api-t1.fyers.in', port=443): Max retries exceeded with url: /data/symbol-token (Caused by NewConnectionError('<urllib3.connection.HTTPSConnection object at 0x000001AB85FF1A90>: Failed to establish a new connection: [Errno 11001] getaddrinfo failed'))","timestamp":"2025-03-13 01:24:12,227+0530","service":"FyersDataSocket","exception":"Traceback (most recent call last):\n  File \"C:\\Conda\\envs\\project_environment\\lib\\site-packages\\websocket\\_http.py\", line 155, in _get_addrinfo_list\n    addrinfo_list = socket.getaddrinfo(\n  File \"C:\\Conda\\envs\\project_environment\\lib\\socket.py\", line 966, in getaddrinfo\n    for res in _socket.getaddrinfo(host, port, family, type, proto, flags):\nsocket.gaierror: [Errno 11001] getaddrinfo failed\n\nDuring handling of the above exception, another exception occurred:\n\nTraceback (most recent call last):\n  File \"C:\\Conda\\envs\\project_environment\\lib\\site-packages\\websocket\\_app.py\", line 412, in setSock\n    self.sock.connect(\n  File \"C:\\Conda\\envs\\project_environment\\lib\\site-packages\\websocket\\_core.py\", line 249, in connect\n    self.sock, addrs = connect(url, self.sock_opt, proxy_info(**options),\n  File \"C:\\Conda\\envs\\project_environment\\lib\\site-packages\\websocket\\_http.py\", line 122, in connect\n    addrinfo_list, need_tunnel, auth = _get_addrinfo_list(\n  File \"C:\\Conda\\envs\\project_environment\\lib\\site-packages\\websocket\\_http.py\", line 167, in _get_addrinfo_list\n    raise WebSocketAddressException(e)\nwebsocket._exceptions.WebSocketAddressException: [Errno 11001] getaddrinfo failed\n\nDuring handling of the above exception, another exception occurred:\n\nTraceback (most recent call last):\n  File \"C:\\Conda\\envs\\project_environment\\lib\\site-packages\\urllib3\\connection.py\", line 174, in _new_conn\n    conn = connection.create_connection(\n  File \"C:\\Conda\\envs\\project_environment\\lib\\site-packages\\urllib3\\util\\connection.py\", line 72, in create_connection\n    for res in socket.getaddrinfo(host, port, family, socket.SOCK_STREAM):\n  File \"C:\\Conda\\envs\\project_environment\\lib\\socket.py\", line 966, in getaddrinfo\n    for res in _socket.getaddrinfo(host, port, family, type, proto, flags):\nsocket.gaierror: [Errno 11001] getaddrinfo failed\n\nDuring handling of the above exception, another exception occurred:\n\nTraceback (most recent call last):\n  File \"C:\\Conda\\envs\\project_environment\\lib\\site-packages\\urllib3\\connectionpool.py\", line 716, in urlopen\n    httplib_response = self._make_request(\n  File \"C:\\Conda\\envs\\project_environment\\lib\\site-packages\\urllib3\\connectionpool.py\", line 404, in _make_request\n    self._validate_conn(conn)\n  File \"C:\\Conda\\envs\\project_environment\\lib\\site-packages\\urllib3\\connectionpool.py\", line 1061, in _validate_conn\n    conn.connect()\n  File \"C:\\Conda\\envs\\project_environment\\lib\\site-packages\\urllib3\\connection.py\", line 363, in connect\n    self.sock = conn = self._new_conn()\n  File \"C:\\Conda\\envs\\project_environment\\lib\\site-packages\\urllib3\\connection.py\", line 186, in _new_conn\n    raise NewConnectionError(\nurllib3.exceptions.NewConnectionError: <urllib3.connection.HTTPSConnection object at 0x000001AB85FF1A90>: Failed to establish a new connection: [Errno 11001] getaddrinfo failed\n\nDuring handling of the above exception, another exception occurred:\n\nTraceback (most recent call last):\n  File \"C:\\Conda\\envs\\project_environment\\lib\\site-packages\\requests\\adapters.py\", line 486, in send\n    resp = conn.urlopen(\n  File \"C:\\Conda\\envs\\project_environment\\lib\\site-packages\\urllib3\\connectionpool.py\", line 802, in urlopen\n    retries = retries.increment(\n  File \"C:\\Conda\\envs\\project_environment\\lib\\site-packages\\urllib3\\util\\retry.py\", line 594, in increment\n    raise MaxRetryError(_pool, url, error or ResponseError(cause))\nurllib3.exceptions.MaxRetryError: HTTPSConnectionPool(host='api-t1.fyers.in', port=443): Max retries exceeded with url: /data/symbol-token (Caused by NewConnectionError('<urllib3.connection.HTTPSConnection object at 0x000001AB85FF1A90>: Failed to establish a new connection: [Errno 11001] getaddrinfo failed'))\n\nDuring handling of the above exception, another exception occurred:\n\nTraceback (most recent call last):\n  File \"C:\\Conda\\envs\\project_environment\\lib\\site-packages\\fyers_apiv3\\FyersWebsocket\\data_ws.py\", line 63, in symbol_to_hsmtoken\n    response = requests.post(\n  File \"C:\\Conda\\envs\\project_environment\\lib\\site-packages\\requests\\api.py\", line 115, in post\n    return request(\"post\", url, data=data, json=json, **kwargs)\n  File \"C:\\Conda\\envs\\project_environment\\lib\\site-packages\\requests\\api.py\", line 59, in request\n    return session.request(method=method, url=url, **kwargs)\n  File \"C:\\Conda\\envs\\project_environment\\lib\\site-packages\\requests\\sessions.py\", line 589, in request\n    resp = self.send(prep, **send_kwargs)\n  File \"C:\\Conda\\envs\\project_environment\\lib\\site-packages\\requests\\sessions.py\", line 703, in send\n    r = adapter.send(request, **kwargs)\n  File \"C:\\Conda\\envs\\project_environment\\lib\\site-packages\\requests\\adapters.py\", line 519, in send\n    raise ConnectionError(e, request=request)\nrequests.exceptions.ConnectionError: HTTPSConnectionPool(host='api-t1.fyers.in', port=443): Max retries exceeded with url: /data/symbol-token (Caused by NewConnectionError('<urllib3.connection.HTTPSConnection object at 0x000001AB85FF1A90>: Failed to establish a new connection: [Errno 11001] getaddrinfo failed'))","exception_name":"ConnectionError"}
{"level":"ERROR","location":"[exception:108] fyers_logger","message":"'NoneType' object is not subscriptable","timestamp":"2025-03-13 01:24:12,493+0530","service":"FyersDataSocket","exception":"Traceback (most recent call last):\n  File \"C:\\Conda\\envs\\project_environment\\lib\\site-packages\\websocket\\_http.py\", line 155, in _get_addrinfo_list\n    addrinfo_list = socket.getaddrinfo(\n  File \"C:\\Conda\\envs\\project_environment\\lib\\socket.py\", line 966, in getaddrinfo\n    for res in _socket.getaddrinfo(host, port, family, type, proto, flags):\nsocket.gaierror: [Errno 11001] getaddrinfo failed\n\nDuring handling of the above exception, another exception occurred:\n\nTraceback (most recent call last):\n  File \"C:\\Conda\\envs\\project_environment\\lib\\site-packages\\websocket\\_app.py\", line 412, in setSock\n    self.sock.connect(\n  File \"C:\\Conda\\envs\\project_environment\\lib\\site-packages\\websocket\\_core.py\", line 249, in connect\n    self.sock, addrs = connect(url, self.sock_opt, proxy_info(**options),\n  File \"C:\\Conda\\envs\\project_environment\\lib\\site-packages\\websocket\\_http.py\", line 122, in connect\n    addrinfo_list, need_tunnel, auth = _get_addrinfo_list(\n  File \"C:\\Conda\\envs\\project_environment\\lib\\site-packages\\websocket\\_http.py\", line 167, in _get_addrinfo_list\n    raise WebSocketAddressException(e)\nwebsocket._exceptions.WebSocketAddressException: [Errno 11001] getaddrinfo failed\n\nDuring handling of the above exception, another exception occurred:\n\nTraceback (most recent call last):\n  File \"C:\\Conda\\envs\\project_environment\\lib\\site-packages\\fyers_apiv3\\FyersWebsocket\\data_ws.py\", line 1333, in __symbol_conversion\n    if symbol_value[3] != \"\":\nTypeError: 'NoneType' object is not subscriptable","exception_name":"TypeError"}
{"level":"ERROR","location":"[exception:108] fyers_logger","message":"HTTPSConnectionPool(host='api-t1.fyers.in', port=443): Max retries exceeded with url: /data/symbol-token (Caused by NewConnectionError('<urllib3.connection.HTTPSConnection object at 0x000001AB82026A30>: Failed to establish a new connection: [WinError 10060] A connection attempt failed because the connected party did not properly respond after a period of time, or established connection failed because connected host has failed to respond'))","timestamp":"2025-03-13 01:24:17,095+0530","service":"FyersDataSocket","exception":"Traceback (most recent call last):\n  File \"C:\\Conda\\envs\\project_environment\\lib\\site-packages\\websocket\\_app.py\", line 428, in setSock\n    dispatcher.read(self.sock.sock, read, check)\n  File \"C:\\Conda\\envs\\project_environment\\lib\\site-packages\\websocket\\_app.py\", line 99, in read\n    if not read_callback():\n  File \"C:\\Conda\\envs\\project_environment\\lib\\site-packages\\websocket\\_app.py\", line 437, in read\n    op_code, frame = self.sock.recv_data_frame(True)\n  File \"C:\\Conda\\envs\\project_environment\\lib\\site-packages\\websocket\\_core.py\", line 406, in recv_data_frame\n    frame = self.recv_frame()\n  File \"C:\\Conda\\envs\\project_environment\\lib\\site-packages\\websocket\\_core.py\", line 445, in recv_frame\n    return self.frame_buffer.recv_frame()\n  File \"C:\\Conda\\envs\\project_environment\\lib\\site-packages\\websocket\\_abnf.py\", line 338, in recv_frame\n    self.recv_header()\n  File \"C:\\Conda\\envs\\project_environment\\lib\\site-packages\\websocket\\_abnf.py\", line 294, in recv_header\n    header = self.recv_strict(2)\n  File \"C:\\Conda\\envs\\project_environment\\lib\\site-packages\\websocket\\_abnf.py\", line 373, in recv_strict\n    bytes_ = self.recv(min(16384, shortage))\n  File \"C:\\Conda\\envs\\project_environment\\lib\\site-packages\\websocket\\_core.py\", line 529, in _recv\n    return recv(self.sock, bufsize)\n  File \"C:\\Conda\\envs\\project_environment\\lib\\site-packages\\websocket\\_socket.py\", line 108, in recv\n    bytes_ = _recv()\n  File \"C:\\Conda\\envs\\project_environment\\lib\\site-packages\\websocket\\_socket.py\", line 87, in _recv\n    return sock.recv(bufsize)\n  File \"C:\\Conda\\envs\\project_environment\\lib\\ssl.py\", line 1260, in recv\n    return self.read(buflen)\n  File \"C:\\Conda\\envs\\project_environment\\lib\\ssl.py\", line 1135, in read\n    return self._sslobj.read(len)\nConnectionResetError: [WinError 10054] An existing connection was forcibly closed by the remote host\n\nDuring handling of the above exception, another exception occurred:\n\nTraceback (most recent call last):\n  File \"C:\\Conda\\envs\\project_environment\\lib\\site-packages\\urllib3\\connection.py\", line 174, in _new_conn\n    conn = connection.create_connection(\n  File \"C:\\Conda\\envs\\project_environment\\lib\\site-packages\\urllib3\\util\\connection.py\", line 95, in create_connection\n    raise err\n  File \"C:\\Conda\\envs\\project_environment\\lib\\site-packages\\urllib3\\util\\connection.py\", line 85, in create_connection\n    sock.connect(sa)\nTimeoutError: [WinError 10060] A connection attempt failed because the connected party did not properly respond after a period of time, or established connection failed because connected host has failed to respond\n\nDuring handling of the above exception, another exception occurred:\n\nTraceback (most recent call last):\n  File \"C:\\Conda\\envs\\project_environment\\lib\\site-packages\\urllib3\\connectionpool.py\", line 716, in urlopen\n    httplib_response = self._make_request(\n  File \"C:\\Conda\\envs\\project_environment\\lib\\site-packages\\urllib3\\connectionpool.py\", line 404, in _make_request\n    self._validate_conn(conn)\n  File \"C:\\Conda\\envs\\project_environment\\lib\\site-packages\\urllib3\\connectionpool.py\", line 1061, in _validate_conn\n    conn.connect()\n  File \"C:\\Conda\\envs\\project_environment\\lib\\site-packages\\urllib3\\connection.py\", line 363, in connect\n    self.sock = conn = self._new_conn()\n  File \"C:\\Conda\\envs\\project_environment\\lib\\site-packages\\urllib3\\connection.py\", line 186, in _new_conn\n    raise NewConnectionError(\nurllib3.exceptions.NewConnectionError: <urllib3.connection.HTTPSConnection object at 0x000001AB82026A30>: Failed to establish a new connection: [WinError 10060] A connection attempt failed because the connected party did not properly respond after a period of time, or established connection failed because connected host has failed to respond\n\nDuring handling of the above exception, another exception occurred:\n\nTraceback (most recent call last):\n  File \"C:\\Conda\\envs\\project_environment\\lib\\site-packages\\requests\\adapters.py\", line 486, in send\n    resp = conn.urlopen(\n  File \"C:\\Conda\\envs\\project_environment\\lib\\site-packages\\urllib3\\connectionpool.py\", line 802, in urlopen\n    retries = retries.increment(\n  File \"C:\\Conda\\envs\\project_environment\\lib\\site-packages\\urllib3\\util\\retry.py\", line 594, in increment\n    raise MaxRetryError(_pool, url, error or ResponseError(cause))\nurllib3.exceptions.MaxRetryError: HTTPSConnectionPool(host='api-t1.fyers.in', port=443): Max retries exceeded with url: /data/symbol-token (Caused by NewConnectionError('<urllib3.connection.HTTPSConnection object at 0x000001AB82026A30>: Failed to establish a new connection: [WinError 10060] A connection attempt failed because the connected party did not properly respond after a period of time, or established connection failed because connected host has failed to respond'))\n\nDuring handling of the above exception, another exception occurred:\n\nTraceback (most recent call last):\n  File \"C:\\Conda\\envs\\project_environment\\lib\\site-packages\\fyers_apiv3\\FyersWebsocket\\data_ws.py\", line 63, in symbol_to_hsmtoken\n    response = requests.post(\n  File \"C:\\Conda\\envs\\project_environment\\lib\\site-packages\\requests\\api.py\", line 115, in post\n    return request(\"post\", url, data=data, json=json, **kwargs)\n  File \"C:\\Conda\\envs\\project_environment\\lib\\site-packages\\requests\\api.py\", line 59, in request\n    return session.request(method=method, url=url, **kwargs)\n  File \"C:\\Conda\\envs\\project_environment\\lib\\site-packages\\requests\\sessions.py\", line 589, in request\n    resp = self.send(prep, **send_kwargs)\n  File \"C:\\Conda\\envs\\project_environment\\lib\\site-packages\\requests\\sessions.py\", line 703, in send\n    r = adapter.send(request, **kwargs)\n  File \"C:\\Conda\\envs\\project_environment\\lib\\site-packages\\requests\\adapters.py\", line 519, in send\n    raise ConnectionError(e, request=request)\nrequests.exceptions.ConnectionError: HTTPSConnectionPool(host='api-t1.fyers.in', port=443): Max retries exceeded with url: /data/symbol-token (Caused by NewConnectionError('<urllib3.connection.HTTPSConnection object at 0x000001AB82026A30>: Failed to establish a new connection: [WinError 10060] A connection attempt failed because the connected party did not properly respond after a period of time, or established connection failed because connected host has failed to respond'))","exception_name":"ConnectionError"}
{"level":"ERROR","location":"[exception:108] fyers_logger","message":"'NoneType' object is not subscriptable","timestamp":"2025-03-13 01:24:17,148+0530","service":"FyersDataSocket","exception":"Traceback (most recent call last):\n  File \"C:\\Conda\\envs\\project_environment\\lib\\site-packages\\websocket\\_app.py\", line 428, in setSock\n    dispatcher.read(self.sock.sock, read, check)\n  File \"C:\\Conda\\envs\\project_environment\\lib\\site-packages\\websocket\\_app.py\", line 99, in read\n    if not read_callback():\n  File \"C:\\Conda\\envs\\project_environment\\lib\\site-packages\\websocket\\_app.py\", line 437, in read\n    op_code, frame = self.sock.recv_data_frame(True)\n  File \"C:\\Conda\\envs\\project_environment\\lib\\site-packages\\websocket\\_core.py\", line 406, in recv_data_frame\n    frame = self.recv_frame()\n  File \"C:\\Conda\\envs\\project_environment\\lib\\site-packages\\websocket\\_core.py\", line 445, in recv_frame\n    return self.frame_buffer.recv_frame()\n  File \"C:\\Conda\\envs\\project_environment\\lib\\site-packages\\websocket\\_abnf.py\", line 338, in recv_frame\n    self.recv_header()\n  File \"C:\\Conda\\envs\\project_environment\\lib\\site-packages\\websocket\\_abnf.py\", line 294, in recv_header\n    header = self.recv_strict(2)\n  File \"C:\\Conda\\envs\\project_environment\\lib\\site-packages\\websocket\\_abnf.py\", line 373, in recv_strict\n    bytes_ = self.recv(min(16384, shortage))\n  File \"C:\\Conda\\envs\\project_environment\\lib\\site-packages\\websocket\\_core.py\", line 529, in _recv\n    return recv(self.sock, bufsize)\n  File \"C:\\Conda\\envs\\project_environment\\lib\\site-packages\\websocket\\_socket.py\", line 108, in recv\n    bytes_ = _recv()\n  File \"C:\\Conda\\envs\\project_environment\\lib\\site-packages\\websocket\\_socket.py\", line 87, in _recv\n    return sock.recv(bufsize)\n  File \"C:\\Conda\\envs\\project_environment\\lib\\ssl.py\", line 1260, in recv\n    return self.read(buflen)\n  File \"C:\\Conda\\envs\\project_environment\\lib\\ssl.py\", line 1135, in read\n    return self._sslobj.read(len)\nConnectionResetError: [WinError 10054] An existing connection was forcibly closed by the remote host\n\nDuring handling of the above exception, another exception occurred:\n\nTraceback (most recent call last):\n  File \"C:\\Conda\\envs\\project_environment\\lib\\site-packages\\fyers_apiv3\\FyersWebsocket\\data_ws.py\", line 1333, in __symbol_conversion\n    if symbol_value[3] != \"\":\nTypeError: 'NoneType' object is not subscriptable","exception_name":"TypeError"}
{"level":"ERROR","location":"[<lambda>:1663] data_ws","message":"[Errno 11001] getaddrinfo failed","timestamp":"2025-03-13 01:24:17,251+0530","service":"FyersDataSocket"}
